2022-08-28 14:28:45,094 ERROR: Exception on /user/admin [GET] [in /Users/danielbianco/Documents/Flask/PA/microblog/venv/lib/python3.10/site-packages/flask/app.py:1457]
Traceback (most recent call last):
  File "/Users/danielbianco/Documents/Flask/PA/microblog/venv/lib/python3.10/site-packages/flask/app.py", line 2073, in wsgi_app
    response = self.full_dispatch_request()
  File "/Users/danielbianco/Documents/Flask/PA/microblog/venv/lib/python3.10/site-packages/flask/app.py", line 1518, in full_dispatch_request
    rv = self.handle_user_exception(e)
  File "/Users/danielbianco/Documents/Flask/PA/microblog/venv/lib/python3.10/site-packages/flask/app.py", line 1516, in full_dispatch_request
    rv = self.dispatch_request()
  File "/Users/danielbianco/Documents/Flask/PA/microblog/venv/lib/python3.10/site-packages/flask/app.py", line 1502, in dispatch_request
    return self.ensure_sync(self.view_functions[rule.endpoint])(**req.view_args)
  File "/Users/danielbianco/Documents/Flask/PA/microblog/venv/lib/python3.10/site-packages/flask_login/utils.py", line 272, in decorated_view
    return func(*args, **kwargs)
  File "/Users/danielbianco/Documents/Flask/PA/microblog/app/routes.py", line 138, in user
    return render_template('user.html', user=user)
  File "/Users/danielbianco/Documents/Flask/PA/microblog/venv/lib/python3.10/site-packages/flask/templating.py", line 147, in render_template
    return _render(
  File "/Users/danielbianco/Documents/Flask/PA/microblog/venv/lib/python3.10/site-packages/flask/templating.py", line 128, in _render
    rv = template.render(context)
  File "/Users/danielbianco/Documents/Flask/PA/microblog/venv/lib/python3.10/site-packages/jinja2/environment.py", line 1291, in render
    self.environment.handle_exception()
  File "/Users/danielbianco/Documents/Flask/PA/microblog/venv/lib/python3.10/site-packages/jinja2/environment.py", line 926, in handle_exception
    raise rewrite_traceback_stack(source=source)
  File "/Users/danielbianco/Documents/Flask/PA/microblog/app/templates/user.html", line 1, in top-level template code
    {% extends "base.html" %}
  File "/Users/danielbianco/Documents/Flask/PA/microblog/app/templates/base.html", line 1, in top-level template code
    {% extends 'bootstrap/base.html' %}
  File "/Users/danielbianco/Documents/Flask/PA/microblog/venv/lib/python3.10/site-packages/flask_bootstrap/templates/bootstrap/base.html", line 1, in top-level template code
    {% block doc -%}
  File "/Users/danielbianco/Documents/Flask/PA/microblog/venv/lib/python3.10/site-packages/flask_bootstrap/templates/bootstrap/base.html", line 4, in block 'doc'
    {%- block html %}
  File "/Users/danielbianco/Documents/Flask/PA/microblog/venv/lib/python3.10/site-packages/flask_bootstrap/templates/bootstrap/base.html", line 20, in block 'html'
    {% block body -%}
  File "/Users/danielbianco/Documents/Flask/PA/microblog/venv/lib/python3.10/site-packages/flask_bootstrap/templates/bootstrap/base.html", line 23, in block 'body'
    {% block content -%}
  File "/Users/danielbianco/Documents/Flask/PA/microblog/app/templates/base.html", line 48, in block 'content'
    {% block app_content %}{% endblock %}
  File "/Users/danielbianco/Documents/Flask/PA/microblog/app/templates/user.html", line 12, in block 'app_content'
    <p>{{ user.followers.count() }} followers, {{ user.followed.count() }} following.</p>
  File "/Users/danielbianco/Documents/Flask/PA/microblog/venv/lib/python3.10/site-packages/jinja2/environment.py", line 475, in getattr
    return getattr(obj, attribute)
jinja2.exceptions.UndefinedError: 'app.models.User object' has no attribute 'followers'
2022-08-28 14:28:46,422 ERROR: Exception on /user/admin [GET] [in /Users/danielbianco/Documents/Flask/PA/microblog/venv/lib/python3.10/site-packages/flask/app.py:1457]
Traceback (most recent call last):
  File "/Users/danielbianco/Documents/Flask/PA/microblog/venv/lib/python3.10/site-packages/flask/app.py", line 2073, in wsgi_app
    response = self.full_dispatch_request()
  File "/Users/danielbianco/Documents/Flask/PA/microblog/venv/lib/python3.10/site-packages/flask/app.py", line 1518, in full_dispatch_request
    rv = self.handle_user_exception(e)
  File "/Users/danielbianco/Documents/Flask/PA/microblog/venv/lib/python3.10/site-packages/flask/app.py", line 1516, in full_dispatch_request
    rv = self.dispatch_request()
  File "/Users/danielbianco/Documents/Flask/PA/microblog/venv/lib/python3.10/site-packages/flask/app.py", line 1502, in dispatch_request
    return self.ensure_sync(self.view_functions[rule.endpoint])(**req.view_args)
  File "/Users/danielbianco/Documents/Flask/PA/microblog/venv/lib/python3.10/site-packages/flask_login/utils.py", line 272, in decorated_view
    return func(*args, **kwargs)
  File "/Users/danielbianco/Documents/Flask/PA/microblog/app/routes.py", line 138, in user
    return render_template('user.html', user=user)
  File "/Users/danielbianco/Documents/Flask/PA/microblog/venv/lib/python3.10/site-packages/flask/templating.py", line 147, in render_template
    return _render(
  File "/Users/danielbianco/Documents/Flask/PA/microblog/venv/lib/python3.10/site-packages/flask/templating.py", line 128, in _render
    rv = template.render(context)
  File "/Users/danielbianco/Documents/Flask/PA/microblog/venv/lib/python3.10/site-packages/jinja2/environment.py", line 1291, in render
    self.environment.handle_exception()
  File "/Users/danielbianco/Documents/Flask/PA/microblog/venv/lib/python3.10/site-packages/jinja2/environment.py", line 926, in handle_exception
    raise rewrite_traceback_stack(source=source)
  File "/Users/danielbianco/Documents/Flask/PA/microblog/app/templates/user.html", line 1, in top-level template code
    {% extends "base.html" %}
  File "/Users/danielbianco/Documents/Flask/PA/microblog/app/templates/base.html", line 1, in top-level template code
    {% extends 'bootstrap/base.html' %}
  File "/Users/danielbianco/Documents/Flask/PA/microblog/venv/lib/python3.10/site-packages/flask_bootstrap/templates/bootstrap/base.html", line 1, in top-level template code
    {% block doc -%}
  File "/Users/danielbianco/Documents/Flask/PA/microblog/venv/lib/python3.10/site-packages/flask_bootstrap/templates/bootstrap/base.html", line 4, in block 'doc'
    {%- block html %}
  File "/Users/danielbianco/Documents/Flask/PA/microblog/venv/lib/python3.10/site-packages/flask_bootstrap/templates/bootstrap/base.html", line 20, in block 'html'
    {% block body -%}
  File "/Users/danielbianco/Documents/Flask/PA/microblog/venv/lib/python3.10/site-packages/flask_bootstrap/templates/bootstrap/base.html", line 23, in block 'body'
    {% block content -%}
  File "/Users/danielbianco/Documents/Flask/PA/microblog/app/templates/base.html", line 48, in block 'content'
    {% block app_content %}{% endblock %}
  File "/Users/danielbianco/Documents/Flask/PA/microblog/app/templates/user.html", line 12, in block 'app_content'
    <p>{{ user.followers.count() }} followers, {{ user.followed.count() }} following.</p>
  File "/Users/danielbianco/Documents/Flask/PA/microblog/venv/lib/python3.10/site-packages/jinja2/environment.py", line 475, in getattr
    return getattr(obj, attribute)
jinja2.exceptions.UndefinedError: 'app.models.User object' has no attribute 'followers'
2022-08-28 14:34:10,626 INFO: Microblog startup [in /Users/danielbianco/Documents/Flask/PA/microblog/app/__init__.py:47]
2022-08-28 14:34:20,799 ERROR: Exception on /index [GET] [in /Users/danielbianco/Documents/Flask/PA/microblog/venv/lib/python3.10/site-packages/flask/app.py:1457]
Traceback (most recent call last):
  File "/Users/danielbianco/Documents/Flask/PA/microblog/venv/lib/python3.10/site-packages/flask/app.py", line 2073, in wsgi_app
    response = self.full_dispatch_request()
  File "/Users/danielbianco/Documents/Flask/PA/microblog/venv/lib/python3.10/site-packages/flask/app.py", line 1518, in full_dispatch_request
    rv = self.handle_user_exception(e)
  File "/Users/danielbianco/Documents/Flask/PA/microblog/venv/lib/python3.10/site-packages/flask/app.py", line 1516, in full_dispatch_request
    rv = self.dispatch_request()
  File "/Users/danielbianco/Documents/Flask/PA/microblog/venv/lib/python3.10/site-packages/flask/app.py", line 1502, in dispatch_request
    return self.ensure_sync(self.view_functions[rule.endpoint])(**req.view_args)
  File "/Users/danielbianco/Documents/Flask/PA/microblog/venv/lib/python3.10/site-packages/flask_login/utils.py", line 272, in decorated_view
    return func(*args, **kwargs)
  File "/Users/danielbianco/Documents/Flask/PA/microblog/app/routes.py", line 31, in index
    posts = current_user.followed_posts().paginate(
  File "/Users/danielbianco/Documents/Flask/PA/microblog/app/models.py", line 57, in followed_posts
    followers, (followers.c.followed_id == Post.user_id)).filter(
AttributeError: type object 'Post' has no attribute 'user_id'
2022-08-28 14:45:57,253 INFO: Microblog startup [in /Users/danielbianco/Documents/Flask/PA/microblog/app/__init__.py:47]
2022-08-28 14:47:50,938 INFO: Microblog startup [in /Users/danielbianco/Documents/Flask/PA/microblog/app/__init__.py:47]
2022-08-28 14:49:13,638 INFO: Microblog startup [in /Users/danielbianco/Documents/Flask/PA/microblog/app/__init__.py:47]
